<mujoco model="dofbot_pro_v24">
  <!-- 1. Default joint parameters go here -->
  <default>
    <joint stiffness="100" damping="5" />
  </default>

  <compiler angle="radian"/>

  <actuator>
    <position name="Arm1_Joint_act" joint="Arm1_Joint"
              kp="200" kv="10" ctrlrange="-1.5708 1.5708"/>
    <position name="Arm2_Joint_act" joint="Arm2_Joint"
              kp="200" kv="10" ctrlrange="-1.5708 1.5708"/>
    <position name="Arm3_Joint_act" joint="Arm3_Joint"
              kp="200" kv="10" ctrlrange="-1.5708 1.5708"/>
    <position name="Arm4_Joint_act" joint="Arm4_Joint"
              kp="200" kv="10" ctrlrange="-1.5708 1.5708"/>
    <position name="Arm5_Joint_act" joint="Arm5_Joint"
              kp="200" kv="10" ctrlrange="-1.5708 3.1416"/>
    <position name="grip_joint_act"  joint="grip_joint"
              kp="50"  kv="5"  ctrlrange="-1.6 0"/>
  </actuator>

  <asset>
    <mesh name="base_link" content_type="model/stl" file="meshes/base_link.STL"/>
    <mesh name="Arm1_Link" content_type="model/stl" file="meshes/Arm1_Link.STL"/>
    <mesh name="Arm2_Link" content_type="model/stl" file="meshes/Arm2_Link.STL"/>
    <mesh name="Arm3_Link" content_type="model/stl" file="meshes/Arm3_Link.STL"/>
    <mesh name="Arm4_Link" content_type="model/obj" file="meshes/Arm4_Link.obj"/>
    <mesh name="DaBai_DCW2_Link" content_type="model/stl" file="meshes/DaBai_DCW2_Link.STL"/>
    <mesh name="Arm5_Link" content_type="model/stl" file="meshes/Arm5_Link.STL"/>
    <mesh name="rlink1" content_type="model/stl" file="meshes/rlink1.STL"/>
    <mesh name="rlink2" content_type="model/stl" file="meshes/rlink2.STL"/>
    <mesh name="llink1" content_type="model/stl" file="meshes/llink1.STL"/>
    <mesh name="llink2" content_type="model/stl" file="meshes/llink2.STL"/>
    <mesh name="rlink3" content_type="model/stl" file="meshes/rlink3.STL"/>
    <mesh name="llink3" content_type="model/stl" file="meshes/llink3.STL"/>
    <mesh name="Gripping_point_Link" content_type="model/stl" file="meshes/Gripping_point_Link.STL"/>
  </asset>

  <worldbody>
    <body name="object_body" quat="0.7071068 0 0 -0.7071068">
      <geom type="mesh" rgba="1 1 1 1" mesh="base_link" pos="-0.5 0 0.06" contype="1" conaffinity="1"/>
    </body>

    <!-- <geom type="mesh" rgba="1 1 1 1" mesh="base_link"/>
    <body name="Arm1_Link" pos="0 0 0.0895"> -->

    <body name="Arm1_Link" pos="0 0.5 0.1495" quat="0.7071068 0 0 -0.7071068"> <!-- The arm -->
      <inertial pos="5.85026e-05 8.08931e-07 0.0151588" quat="9.54251e-06 0.707107 -1.20655e-05 0.707107" mass="0.0190944" diaginertia="4.26796e-06 3.23898e-06 2.63e-06"/>
      <joint name="Arm1_Joint" pos="0 0 0" axis="0 0 1" range="-1.5708 1.5708" actuatorfrcrange="-100 100"/>
      <geom type="mesh" rgba="1 1 1 1" mesh="Arm1_Link"/>
      <body name="Arm2_Link" pos="0 0 0.033">
        <inertial pos="0.000130416 -0.00344479 0.0308784" quat="0.707646 0.00433241 0.00588337 0.70653" mass="0.0490166" diaginertia="1.752e-05 1.39175e-05 7.83531e-06"/>
        <joint name="Arm2_Joint" pos="0 0 0" axis="1 0 0" range="-1.5708 1.5708" actuatorfrcrange="-100 100"/>
        <geom type="mesh" rgba="1 1 1 1" mesh="Arm2_Link"/>
        <body name="Arm3_Link" pos="-0.00055 0 0.08285">
          <inertial pos="0.000230967 -0.00348204 0.0312592" quat="0.707645 0.00438014 0.00593195 0.70653" mass="0.0484404" diaginertia="1.7508e-05 1.38992e-05 7.82716e-06"/>
          <joint name="Arm3_Joint" pos="0 0 0" axis="1 0 0" range="-1.5708 1.5708" actuatorfrcrange="-100 100"/>
          <geom type="mesh" rgba="1 1 1 1" mesh="Arm3_Link"/>
          <body name="Arm4_Link" pos="-5e-05 0 0.08285" quat="0.707107 0.707107 0 0">
            <inertial pos="-0.000333227 0.0435755 0.0178058" quat="0.653706 -0.239136 0.226861 0.681188" mass="0.0807892" diaginertia="8.62083e-05 7.60956e-05 2.78774e-05"/>
            <joint name="Arm4_Joint" pos="0 0 0" axis="1 0 0" range="-1.5708 1.5708" actuatorfrcrange="-100 100"/>
            <geom type="mesh" rgba="1 1 1 1" mesh="Arm4_Link"/>
            <geom pos="-0.0002 0.0689 0.0506" quat="0.99999 0.00436331 0 0" type="mesh" rgba="0.25098 0.25098 0.25098 1" mesh="DaBai_DCW2_Link"/>

            <!-- Add camera attached to the DaBai_DCW2_Link position -->
            <!-- <camera name="wrist_camera"
                pos="-0.0002 0.0889 0.0506" 
                quat="0.707 0.707 0 0"
                fovy="85" 
                ipd="0.068"/> -->

            <camera name="wrist_camera"
                pos="-0.0002 0.0889 0.0506" 
                euler="1.4008 0 0"
                fovy="85" 
                ipd="0.068"/>

            <!-- <camera name="front_camera" 
                pos="0.5 -0.01 0.2"
                euler="0.4 1.0 1.98"
                fovy="45" 
                ipd="0.068"/> -->
                <!-- rpy -->

            <!-- <camera name="front_camera" 
                pos="0.5 0.15 0.2"
                euler="0.4 1.2 1.98"
                fovy="45" 
                ipd="0.068"/> -->

            <camera name="front_camera" 
                pos="0.5 0.05 0.2"
                euler="0.6 1.25 1.98"
                fovy="45" 
                ipd="0.068"/>

                <!-- manageable view euler="0.8 0 0"  similar to -> quat="0.924 0.383 0 0"-->
                <!-- best view so far quat="0.707 0.707 0 0" -->

            <body name="Arm5_Link" pos="0 0.078149 0.00215">
              <inertial pos="0.0021813 0.0258955 -0.0140283" quat="0.573694 0.407221 0.592547 0.392344" mass="0.0552577" diaginertia="1.05893e-05 9.38262e-06 6.25638e-06"/>
              <joint name="Arm5_Joint" pos="0 0 0" axis="0 -1 0" range="-1.5708 3.1416" actuatorfrcrange="-100 100"/>
              <geom type="mesh" rgba="0.25098 0.25098 0.25098 1" mesh="Arm5_Link"/>
              <geom pos="0 0.09 0" quat="1 0 0 0" type="mesh" rgba="1 1 1 1" mesh="Gripping_point_Link"/>
              <body name="rlink1" pos="0.012625 0.029275 0.00475" quat="0.977611 0 0 0.21042">
                <inertial pos="0.00749117 -0.00307322 -0.000464636" quat="0.166899 0.687128 -0.166899 0.687128" mass="0.00469662" diaginertia="5.45545e-07 4.53632e-07 1.01494e-07"/>
                <joint name="grip_joint" pos="0 0 0" axis="0 0 -1" range="-1.6 0" actuatorfrcrange="-100 100"/>
                <geom type="mesh" rgba="1 1 1 1" mesh="rlink1"/>

                <site name="grip_site" pos="0 0.09 0" size="0.002" rgba="1 0 0 1" type="sphere"/>
                
                <body name="rlink2" pos="0.027229 -0.012593 -0.0025" quat="0.840061 0 0 0.542491">
                  <inertial pos="0.0226141 0.00598033 -0.0015" quat="-0.0554899 0.704926 0.0554899 0.704926" mass="0.00614487" diaginertia="1.57602e-06 1.5385e-06 4.67285e-08"/>
                  <joint name="rlink_joint2" pos="0 0 0" axis="0 0 1"/>
                  <geom type="mesh" rgba="1 1 1 1" mesh="rlink2"/>
                </body>
              </body>
              <body name="llink1" pos="-0.012375 0.029275 0.0045" quat="0.204738 0 0 0.978817">
                <inertial pos="0.00820826 0.00331563 -0.000169456" quat="-0.160561 0.688636 0.160561 0.688636" mass="0.00426701" diaginertia="5.36666e-07 4.55979e-07 8.79672e-08"/>
                <joint name="llink_joint1" pos="0 0 0" axis="0 0 1"/>
                <geom type="mesh" rgba="1 1 1 1" mesh="llink1"/>
                <body name="llink2" pos="0.027362 0.012302 -0.0025" quat="0.836901 0 0 -0.547355">
                  <inertial pos="0.0226936 -0.00567118 -0.0015" quat="0.0506787 0.705288 -0.0506787 0.705288" mass="0.00614487" diaginertia="1.57602e-06 1.5385e-06 4.67285e-08"/>
                  <joint name="llink_joint2" pos="0 0 0" axis="0 0 1"/>
                  <geom type="mesh" rgba="1 1 1 1" mesh="llink2"/>
                </body>
              </body>
              <body name="rlink3" pos="0.0045 0.047275 0.0045" quat="0.977611 0 0 0.21042">
                <inertial pos="0.0134815 -0.0060854 -0.0027141" quat="0.594015 0.594015 0.383596 0.383596" mass="0.00270972" diaginertia="1.63608e-07 1.63255e-07 9.18475e-09"/>
                <joint name="rlink_joint3" pos="0 0 0" axis="0 0 1"/>
                <geom type="mesh" rgba="1 1 1 1" mesh="rlink3"/>
              </body>
              <body name="llink3" pos="-0.0045 0.047275 0.0045" quat="0.204738 0 0 0.978817">
                <inertial pos="0.0135673 0.00589169 -0.0027141" quat="0.38784 0.38784 0.591253 0.591253" mass="0.00270972" diaginertia="1.63608e-07 1.63255e-07 9.18475e-09"/>
                <joint name="llink_joint3" pos="0 0 0" axis="0 0 1"/>
                <geom type="mesh" rgba="1 1 1 1" mesh="llink3"/>
              </body>
            </body>
          </body>
        </body>
      </body>
    </body>
  </worldbody>
</mujoco>
